Workbook

Sheet SkyreelsV2-Chunkwise
A1: num_frames | B1: 177
A2: ar_step | B2: 5
A3: causal_block_size | B3: 5
A4: base_num_frames | B4: 97
A5: overlap_history | B5: 17
A6: inference_steps | B6: 25
A7: cnt | B7: 40 | E7: num_steps | F7: =IF(B8>1,B6+(((B4-1)/4+1)/B3-1)*B2-B2,B6+(((B4-1)/4+1)/B3-1)*B2) -> 45 | I7: block1 | J7: 1
A8: n_iter | B8: 1 | E8: max_n_iter | F8: =1+FLOOR((B29-B31-1)/(B31-B30),1)+1 -> 2 | I8: block2 | J8: 2
A9: addnoise_condition | B9: 20 | E9: sum_steps | F9: =B6+(((B4-1)/4+1)/B3-1)*B2+(F8-1)*(B6+(((B4-1)/4+1)/B3-1)*B2-B2) -> 85 | I9: block3 | J9: 3
A10: guidance_scale | B10: 6 | I10: block4 | J10: 4
A11: shift | B11: 8 | E11: ret_steps | F11: 5 | I11: block5 | J11: 5
A12: fps | B12: 24 | E12: cutoff_steps | F12: =B6 -> 25
A13: height | B13: 544
A14: width | B14: 960
A15: in_dim | B15: 16
A16: out_dim | B16: 64
A17: dim | B17: 1536
A18: ffn_dim | B18: 8960
A19: freq_dim | B19: 256
A20: num_heads | B20: 12
A21: head_dim | B21: 128
A22: text_len | B22: 512
A23: text_dim | B23: 4096
A24: num_layers | B24: 30
A25: patch_size | B25: 1,2,2
A27: latent_height | B27: =B13/8 -> 68 | E27: output_video | F27: =B8>1 -> FALSE
A28: latent_width | B28: =B14/8 -> 120 | E28: step_update_mask | F28: =IF(AND(B8>1,J7=1),FALSE,AND(B7>=(J7-1)*B2+1,B7<=(J7-1)*B2+B6)) -> FALSE | G28: =IF(AND(B8>1,J8=1),FALSE,AND(B7>=(J8-1)*B2+1,B7<=(J8-1)*B2+B6)) -> FALSE | H28: =IF(AND(B8>1,J9=1),FALSE,AND(B7>=(J9-1)*B2+1,B7<=(J9-1)*B2+B6)) -> FALSE | I28: =IF(AND(B8>1,J10=1),FALSE,AND(B7>=(J10-1)*B2+1,B7<=(J10-1)*B2+B6)) -> TRUE | J28: =IF(AND(B8>1,J11=1),FALSE,AND(B7>=(J11-1)*B2+1,B7<=(J11-1)*B2+B6)) -> TRUE
A29: latent_length | B29: =(B1-1)/4+1 -> 45 | E29: should_forward_mask | F29: =IF(AND(B8>1,J7=1),TRUE,B7>=(J7-1)*B2+1) -> TRUE | G29: =IF(AND(B8>1,J8=1),TRUE,B7>=(J8-1)*B2+1) -> TRUE | H29: =IF(AND(B8>1,J9=1),TRUE,B7>=(J9-1)*B2+1) -> TRUE | I29: =IF(AND(B8>1,J10=1),TRUE,B7>=(J10-1)*B2+1) -> TRUE | J29: =IF(AND(B8>1,J11=1),TRUE,B7>=(J11-1)*B2+1) -> TRUE
A30: overlap_history_frames | B30: =(B5-1)/4+1 -> 5
A31: base_num_frames | B31: =(B4-1)/4+1 -> 25
A32: group_size | B32: =B3 -> 5
A33: num_groups | B33: =B31/B32 -> 5
A34: token_per_frame | B34: =(B27/2)*(B28/2) -> 2040
A35: token_per_block | B35: =B34*B32 -> 10200
A36: token_per_chunk | B36: =B35*B33 -> 51000
B40: Params (GB) | C40: TFlops | D40: MLP+Attn Params (GB) | E40: MLP+Attn Params占比 (%) | F40: Condition和Head Params (GB) | G40: Condition和Head Params占比 (%) | H40: FA TFlops | I40: FA Flops占比 (%) | J40: GEMM TFlops | K40: GEMM Flops占比 (%)
A41: VideoDiTModel | B41: =O72 -> 2.6720266 | C41: =P72 -> 420.82988 | D41: =E74*B24 -> 2.5932884 | E41: =(D41/B41)*100 -> 97.05324 | F41: =O62+O50 -> 0.078738213 | G41: =(F41/B41)*100 -> 2.94676 | H41: =(K54+K55+K65+K66)*B24 -> 292.46276 | I41: =(H41/C41)*100 -> 69.496671 | J41: =B24*(K50+K51+K52+K53+K61+K62+K63+K64+K71+K72)+P49+P58+P59+P60+P61 -> 128.28808 | K41: =(J41/C41)*100 -> 30.484547
B45: VideoDiTModel
F46: block1 | G46: block2 | H46: block3 | I46: block4 | J46: block5
E47: Params | F47: TFlops | G47: TFlops | H47: TFlops | I47: TFlops | J47: TFlops | K47: ToTal | O47: Params | P47: TFlops
...

Sheet Base
A1: Params Base (GB) | B1: =1024*1024*1024 -> 1073741824
A2: TFlops Base (T) | B2: =1000*1000*1000*1000 -> 1000000000000
A3: Comm Base (MB) | B3: =1024*1024*1024 -> 1073741824
